<?xml version="1.0" encoding="UTF-8"?>
<robot generator="Robot 3.2.1 (Python 3.8.3 on win32)" generated="20200723 07:28:54.636" rpa="false">
<suite id="s1" name="TC 004 getvalues" source="C:\Users\Subhashini\PycharmProjects\RobotAutomation\Testcases\Fetch Data\TC_004_getvalues.robot">
<test id="s1-t1" name="Robot First test case">
<kw name="Create folder at Runtime">
<msg timestamp="20200723 07:28:55.127" level="FAIL">No keyword with name 'Create folder at Runtime' found.</msg>
<status status="FAIL" starttime="20200723 07:28:55.127" endtime="20200723 07:28:55.127"></status>
</kw>
<status status="FAIL" starttime="20200723 07:28:55.119" endtime="20200723 07:28:55.127" critical="yes">No keyword with name 'Create folder at Runtime' found.</status>
</test>
<status status="FAIL" starttime="20200723 07:28:54.640" endtime="20200723 07:28:55.132"></status>
</suite>
<statistics>
<total>
<stat pass="0" fail="1">Critical Tests</stat>
<stat pass="0" fail="1">All Tests</stat>
</total>
<tag>
</tag>
<suite>
<stat pass="0" fail="1" id="s1" name="TC 004 getvalues">TC 004 getvalues</stat>
</suite>
</statistics>
<errors>
<msg timestamp="20200723 07:28:55.116" level="ERROR">Error in file 'C:\Users\Subhashini\PycharmProjects\RobotAutomation\Testcases\Fetch Data\TC_004_getvalues.robot' on line 3: Resource file '..\Resources\Resource2.robot' does not exist.</msg>
</errors>
</robot>
